INFO - 2023-04-25 02:56:17,934 - process: 7580 - scheduler.py - gerapy.server.core.scheduler - 105 - scheduler - successfully synced task with jobs with force
ERROR - 2023-04-25 02:57:10,534 - process: 7580 - utils.py - gerapy.server.core.utils - 564 - utils - [WinError 3] 系统找不到指定的路径。: 'E:\\tuling\\tl\\travel\\gerapyDemo\\gerapy\\projects\\spider_ly\\projects\\spider_ly'
Traceback (most recent call last):
  File "C:\Users\86166\AppData\Local\Programs\Python\Python310\lib\site-packages\gerapy\server\core\utils.py", line 562, in wrapper
    result = func(*args, **kwargs)
  File "C:\Users\86166\AppData\Local\Programs\Python\Python310\lib\site-packages\django\views\decorators\csrf.py", line 54, in wrapped_view
    return view_func(*args, **kwargs)
  File "C:\Users\86166\AppData\Local\Programs\Python\Python310\lib\site-packages\django\views\generic\base.py", line 71, in view
    return self.dispatch(request, *args, **kwargs)
  File "C:\Users\86166\AppData\Local\Programs\Python\Python310\lib\site-packages\rest_framework\views.py", line 509, in dispatch
    response = self.handle_exception(exc)
  File "C:\Users\86166\AppData\Local\Programs\Python\Python310\lib\site-packages\rest_framework\views.py", line 469, in handle_exception
    self.raise_uncaught_exception(exc)
  File "C:\Users\86166\AppData\Local\Programs\Python\Python310\lib\site-packages\rest_framework\views.py", line 480, in raise_uncaught_exception
    raise exc
  File "C:\Users\86166\AppData\Local\Programs\Python\Python310\lib\site-packages\rest_framework\views.py", line 506, in dispatch
    response = handler(request, *args, **kwargs)
  File "C:\Users\86166\AppData\Local\Programs\Python\Python310\lib\site-packages\rest_framework\decorators.py", line 50, in handler
    return func(*args, **kwargs)
  File "C:\Users\86166\AppData\Local\Programs\Python\Python310\lib\site-packages\gerapy\server\core\views.py", line 452, in project_deploy
    egg = find_egg(project_path)
  File "C:\Users\86166\AppData\Local\Programs\Python\Python310\lib\site-packages\gerapy\server\core\build.py", line 89, in find_egg
    items = os.listdir(path)
FileNotFoundError: [WinError 3] 系统找不到指定的路径。: 'E:\\tuling\\tl\\travel\\gerapyDemo\\gerapy\\projects\\spider_ly\\projects\\spider_ly'
INFO - 2023-04-25 02:57:11,393 - process: 7580 - build.py - gerapy.server.core.build - 24 - build - successfully build project spider_ly to egg file E:\tuling\tl\travel\gerapyDemo\gerapy\projects\spider_ly\project-1.0-py3.10.egg
ERROR - 2023-04-25 02:57:22,336 - process: 7580 - utils.py - gerapy.server.core.utils - 564 - utils - database is locked
Traceback (most recent call last):
  File "C:\Users\86166\AppData\Local\Programs\Python\Python310\lib\site-packages\django\db\models\query.py", line 554, in update_or_create
    obj = self.select_for_update().get(**kwargs)
  File "C:\Users\86166\AppData\Local\Programs\Python\Python310\lib\site-packages\django\db\models\query.py", line 406, in get
    raise self.model.DoesNotExist(
gerapy.server.core.models.Deploy.DoesNotExist: Deploy matching query does not exist.

During handling of the above exception, another exception occurred:

Traceback (most recent call last):
  File "C:\Users\86166\AppData\Local\Programs\Python\Python310\lib\site-packages\django\db\backends\utils.py", line 84, in _execute
    return self.cursor.execute(sql, params)
  File "C:\Users\86166\AppData\Local\Programs\Python\Python310\lib\site-packages\django\db\backends\sqlite3\base.py", line 383, in execute
    return Database.Cursor.execute(self, query, params)
sqlite3.OperationalError: database is locked

The above exception was the direct cause of the following exception:

Traceback (most recent call last):
  File "C:\Users\86166\AppData\Local\Programs\Python\Python310\lib\site-packages\gerapy\server\core\utils.py", line 562, in wrapper
    result = func(*args, **kwargs)
  File "C:\Users\86166\AppData\Local\Programs\Python\Python310\lib\site-packages\django\views\decorators\csrf.py", line 54, in wrapped_view
    return view_func(*args, **kwargs)
  File "C:\Users\86166\AppData\Local\Programs\Python\Python310\lib\site-packages\django\views\generic\base.py", line 71, in view
    return self.dispatch(request, *args, **kwargs)
  File "C:\Users\86166\AppData\Local\Programs\Python\Python310\lib\site-packages\rest_framework\views.py", line 509, in dispatch
    response = self.handle_exception(exc)
  File "C:\Users\86166\AppData\Local\Programs\Python\Python310\lib\site-packages\rest_framework\views.py", line 469, in handle_exception
    self.raise_uncaught_exception(exc)
  File "C:\Users\86166\AppData\Local\Programs\Python\Python310\lib\site-packages\rest_framework\views.py", line 480, in raise_uncaught_exception
    raise exc
  File "C:\Users\86166\AppData\Local\Programs\Python\Python310\lib\site-packages\rest_framework\views.py", line 506, in dispatch
    response = handler(request, *args, **kwargs)
  File "C:\Users\86166\AppData\Local\Programs\Python\Python310\lib\site-packages\rest_framework\decorators.py", line 50, in handler
    return func(*args, **kwargs)
  File "C:\Users\86166\AppData\Local\Programs\Python\Python310\lib\site-packages\gerapy\server\core\views.py", line 465, in project_deploy
    deploy, result = Deploy.objects.update_or_create(client=client, project=project, deployed_at=deployed_at,
  File "C:\Users\86166\AppData\Local\Programs\Python\Python310\lib\site-packages\django\db\models\manager.py", line 82, in manager_method
    return getattr(self.get_queryset(), name)(*args, **kwargs)
  File "C:\Users\86166\AppData\Local\Programs\Python\Python310\lib\site-packages\django\db\models\query.py", line 559, in update_or_create
    obj, created = self._create_object_from_params(kwargs, params, lock=True)
  File "C:\Users\86166\AppData\Local\Programs\Python\Python310\lib\site-packages\django\db\models\query.py", line 575, in _create_object_from_params
    obj = self.create(**params)
  File "C:\Users\86166\AppData\Local\Programs\Python\Python310\lib\site-packages\django\db\models\query.py", line 422, in create
    obj.save(force_insert=True, using=self.db)
  File "C:\Users\86166\AppData\Local\Programs\Python\Python310\lib\site-packages\django\db\models\base.py", line 743, in save
    self.save_base(using=using, force_insert=force_insert,
  File "C:\Users\86166\AppData\Local\Programs\Python\Python310\lib\site-packages\django\db\models\base.py", line 780, in save_base
    updated = self._save_table(
  File "C:\Users\86166\AppData\Local\Programs\Python\Python310\lib\site-packages\django\db\models\base.py", line 873, in _save_table
    result = self._do_insert(cls._base_manager, using, fields, update_pk, raw)
  File "C:\Users\86166\AppData\Local\Programs\Python\Python310\lib\site-packages\django\db\models\base.py", line 910, in _do_insert
    return manager._insert([self], fields=fields, return_id=update_pk,
  File "C:\Users\86166\AppData\Local\Programs\Python\Python310\lib\site-packages\django\db\models\manager.py", line 82, in manager_method
    return getattr(self.get_queryset(), name)(*args, **kwargs)
  File "C:\Users\86166\AppData\Local\Programs\Python\Python310\lib\site-packages\django\db\models\query.py", line 1186, in _insert
    return query.get_compiler(using=using).execute_sql(return_id)
  File "C:\Users\86166\AppData\Local\Programs\Python\Python310\lib\site-packages\django\db\models\sql\compiler.py", line 1377, in execute_sql
    cursor.execute(sql, params)
  File "C:\Users\86166\AppData\Local\Programs\Python\Python310\lib\site-packages\django\db\backends\utils.py", line 99, in execute
    return super().execute(sql, params)
  File "C:\Users\86166\AppData\Local\Programs\Python\Python310\lib\site-packages\django\db\backends\utils.py", line 67, in execute
    return self._execute_with_wrappers(sql, params, many=False, executor=self._execute)
  File "C:\Users\86166\AppData\Local\Programs\Python\Python310\lib\site-packages\django\db\backends\utils.py", line 76, in _execute_with_wrappers
    return executor(sql, params, many, context)
  File "C:\Users\86166\AppData\Local\Programs\Python\Python310\lib\site-packages\django\db\backends\utils.py", line 80, in _execute
    with self.db.wrap_database_errors:
  File "C:\Users\86166\AppData\Local\Programs\Python\Python310\lib\site-packages\django\db\utils.py", line 89, in __exit__
    raise dj_exc_value.with_traceback(traceback) from exc_value
  File "C:\Users\86166\AppData\Local\Programs\Python\Python310\lib\site-packages\django\db\backends\utils.py", line 84, in _execute
    return self.cursor.execute(sql, params)
  File "C:\Users\86166\AppData\Local\Programs\Python\Python310\lib\site-packages\django\db\backends\sqlite3\base.py", line 383, in execute
    return Database.Cursor.execute(self, query, params)
django.db.utils.OperationalError: database is locked
ERROR - 2023-04-25 02:58:58,926 - process: 7580 - utils.py - gerapy.server.core.utils - 564 - utils - database is locked
Traceback (most recent call last):
  File "C:\Users\86166\AppData\Local\Programs\Python\Python310\lib\site-packages\django\db\models\query.py", line 554, in update_or_create
    obj = self.select_for_update().get(**kwargs)
  File "C:\Users\86166\AppData\Local\Programs\Python\Python310\lib\site-packages\django\db\models\query.py", line 406, in get
    raise self.model.DoesNotExist(
gerapy.server.core.models.Deploy.DoesNotExist: Deploy matching query does not exist.

During handling of the above exception, another exception occurred:

Traceback (most recent call last):
  File "C:\Users\86166\AppData\Local\Programs\Python\Python310\lib\site-packages\django\db\backends\utils.py", line 84, in _execute
    return self.cursor.execute(sql, params)
  File "C:\Users\86166\AppData\Local\Programs\Python\Python310\lib\site-packages\django\db\backends\sqlite3\base.py", line 383, in execute
    return Database.Cursor.execute(self, query, params)
sqlite3.OperationalError: database is locked

The above exception was the direct cause of the following exception:

Traceback (most recent call last):
  File "C:\Users\86166\AppData\Local\Programs\Python\Python310\lib\site-packages\gerapy\server\core\utils.py", line 562, in wrapper
    result = func(*args, **kwargs)
  File "C:\Users\86166\AppData\Local\Programs\Python\Python310\lib\site-packages\django\views\decorators\csrf.py", line 54, in wrapped_view
    return view_func(*args, **kwargs)
  File "C:\Users\86166\AppData\Local\Programs\Python\Python310\lib\site-packages\django\views\generic\base.py", line 71, in view
    return self.dispatch(request, *args, **kwargs)
  File "C:\Users\86166\AppData\Local\Programs\Python\Python310\lib\site-packages\rest_framework\views.py", line 509, in dispatch
    response = self.handle_exception(exc)
  File "C:\Users\86166\AppData\Local\Programs\Python\Python310\lib\site-packages\rest_framework\views.py", line 469, in handle_exception
    self.raise_uncaught_exception(exc)
  File "C:\Users\86166\AppData\Local\Programs\Python\Python310\lib\site-packages\rest_framework\views.py", line 480, in raise_uncaught_exception
    raise exc
  File "C:\Users\86166\AppData\Local\Programs\Python\Python310\lib\site-packages\rest_framework\views.py", line 506, in dispatch
    response = handler(request, *args, **kwargs)
  File "C:\Users\86166\AppData\Local\Programs\Python\Python310\lib\site-packages\rest_framework\decorators.py", line 50, in handler
    return func(*args, **kwargs)
  File "C:\Users\86166\AppData\Local\Programs\Python\Python310\lib\site-packages\gerapy\server\core\views.py", line 430, in project_version
    deploy, result = Deploy.objects.update_or_create(
  File "C:\Users\86166\AppData\Local\Programs\Python\Python310\lib\site-packages\django\db\models\manager.py", line 82, in manager_method
    return getattr(self.get_queryset(), name)(*args, **kwargs)
  File "C:\Users\86166\AppData\Local\Programs\Python\Python310\lib\site-packages\django\db\models\query.py", line 559, in update_or_create
    obj, created = self._create_object_from_params(kwargs, params, lock=True)
  File "C:\Users\86166\AppData\Local\Programs\Python\Python310\lib\site-packages\django\db\models\query.py", line 575, in _create_object_from_params
    obj = self.create(**params)
  File "C:\Users\86166\AppData\Local\Programs\Python\Python310\lib\site-packages\django\db\models\query.py", line 422, in create
    obj.save(force_insert=True, using=self.db)
  File "C:\Users\86166\AppData\Local\Programs\Python\Python310\lib\site-packages\django\db\models\base.py", line 743, in save
    self.save_base(using=using, force_insert=force_insert,
  File "C:\Users\86166\AppData\Local\Programs\Python\Python310\lib\site-packages\django\db\models\base.py", line 780, in save_base
    updated = self._save_table(
  File "C:\Users\86166\AppData\Local\Programs\Python\Python310\lib\site-packages\django\db\models\base.py", line 873, in _save_table
    result = self._do_insert(cls._base_manager, using, fields, update_pk, raw)
  File "C:\Users\86166\AppData\Local\Programs\Python\Python310\lib\site-packages\django\db\models\base.py", line 910, in _do_insert
    return manager._insert([self], fields=fields, return_id=update_pk,
  File "C:\Users\86166\AppData\Local\Programs\Python\Python310\lib\site-packages\django\db\models\manager.py", line 82, in manager_method
    return getattr(self.get_queryset(), name)(*args, **kwargs)
  File "C:\Users\86166\AppData\Local\Programs\Python\Python310\lib\site-packages\django\db\models\query.py", line 1186, in _insert
    return query.get_compiler(using=using).execute_sql(return_id)
  File "C:\Users\86166\AppData\Local\Programs\Python\Python310\lib\site-packages\django\db\models\sql\compiler.py", line 1377, in execute_sql
    cursor.execute(sql, params)
  File "C:\Users\86166\AppData\Local\Programs\Python\Python310\lib\site-packages\django\db\backends\utils.py", line 99, in execute
    return super().execute(sql, params)
  File "C:\Users\86166\AppData\Local\Programs\Python\Python310\lib\site-packages\django\db\backends\utils.py", line 67, in execute
    return self._execute_with_wrappers(sql, params, many=False, executor=self._execute)
  File "C:\Users\86166\AppData\Local\Programs\Python\Python310\lib\site-packages\django\db\backends\utils.py", line 76, in _execute_with_wrappers
    return executor(sql, params, many, context)
  File "C:\Users\86166\AppData\Local\Programs\Python\Python310\lib\site-packages\django\db\backends\utils.py", line 80, in _execute
    with self.db.wrap_database_errors:
  File "C:\Users\86166\AppData\Local\Programs\Python\Python310\lib\site-packages\django\db\utils.py", line 89, in __exit__
    raise dj_exc_value.with_traceback(traceback) from exc_value
  File "C:\Users\86166\AppData\Local\Programs\Python\Python310\lib\site-packages\django\db\backends\utils.py", line 84, in _execute
    return self.cursor.execute(sql, params)
  File "C:\Users\86166\AppData\Local\Programs\Python\Python310\lib\site-packages\django\db\backends\sqlite3\base.py", line 383, in execute
    return Database.Cursor.execute(self, query, params)
django.db.utils.OperationalError: database is locked
INFO - 2023-04-25 02:59:11,565 - process: 7580 - build.py - gerapy.server.core.build - 24 - build - successfully build project spider_ly to egg file E:\tuling\tl\travel\gerapyDemo\gerapy\projects\spider_ly\project-1.0-py3.10.egg
ERROR - 2023-04-25 03:03:06,431 - process: 7580 - utils.py - gerapy.server.core.utils - 564 - utils - database is locked
Traceback (most recent call last):
  File "C:\Users\86166\AppData\Local\Programs\Python\Python310\lib\site-packages\django\db\models\query.py", line 554, in update_or_create
    obj = self.select_for_update().get(**kwargs)
  File "C:\Users\86166\AppData\Local\Programs\Python\Python310\lib\site-packages\django\db\models\query.py", line 406, in get
    raise self.model.DoesNotExist(
gerapy.server.core.models.Deploy.DoesNotExist: Deploy matching query does not exist.

During handling of the above exception, another exception occurred:

Traceback (most recent call last):
  File "C:\Users\86166\AppData\Local\Programs\Python\Python310\lib\site-packages\django\db\backends\utils.py", line 84, in _execute
    return self.cursor.execute(sql, params)
  File "C:\Users\86166\AppData\Local\Programs\Python\Python310\lib\site-packages\django\db\backends\sqlite3\base.py", line 383, in execute
    return Database.Cursor.execute(self, query, params)
sqlite3.OperationalError: database is locked

The above exception was the direct cause of the following exception:

Traceback (most recent call last):
  File "C:\Users\86166\AppData\Local\Programs\Python\Python310\lib\site-packages\gerapy\server\core\utils.py", line 562, in wrapper
    result = func(*args, **kwargs)
  File "C:\Users\86166\AppData\Local\Programs\Python\Python310\lib\site-packages\django\views\decorators\csrf.py", line 54, in wrapped_view
    return view_func(*args, **kwargs)
  File "C:\Users\86166\AppData\Local\Programs\Python\Python310\lib\site-packages\django\views\generic\base.py", line 71, in view
    return self.dispatch(request, *args, **kwargs)
  File "C:\Users\86166\AppData\Local\Programs\Python\Python310\lib\site-packages\rest_framework\views.py", line 509, in dispatch
    response = self.handle_exception(exc)
  File "C:\Users\86166\AppData\Local\Programs\Python\Python310\lib\site-packages\rest_framework\views.py", line 469, in handle_exception
    self.raise_uncaught_exception(exc)
  File "C:\Users\86166\AppData\Local\Programs\Python\Python310\lib\site-packages\rest_framework\views.py", line 480, in raise_uncaught_exception
    raise exc
  File "C:\Users\86166\AppData\Local\Programs\Python\Python310\lib\site-packages\rest_framework\views.py", line 506, in dispatch
    response = handler(request, *args, **kwargs)
  File "C:\Users\86166\AppData\Local\Programs\Python\Python310\lib\site-packages\rest_framework\decorators.py", line 50, in handler
    return func(*args, **kwargs)
  File "C:\Users\86166\AppData\Local\Programs\Python\Python310\lib\site-packages\gerapy\server\core\views.py", line 430, in project_version
    deploy, result = Deploy.objects.update_or_create(
  File "C:\Users\86166\AppData\Local\Programs\Python\Python310\lib\site-packages\django\db\models\manager.py", line 82, in manager_method
    return getattr(self.get_queryset(), name)(*args, **kwargs)
  File "C:\Users\86166\AppData\Local\Programs\Python\Python310\lib\site-packages\django\db\models\query.py", line 559, in update_or_create
    obj, created = self._create_object_from_params(kwargs, params, lock=True)
  File "C:\Users\86166\AppData\Local\Programs\Python\Python310\lib\site-packages\django\db\models\query.py", line 575, in _create_object_from_params
    obj = self.create(**params)
  File "C:\Users\86166\AppData\Local\Programs\Python\Python310\lib\site-packages\django\db\models\query.py", line 422, in create
    obj.save(force_insert=True, using=self.db)
  File "C:\Users\86166\AppData\Local\Programs\Python\Python310\lib\site-packages\django\db\models\base.py", line 743, in save
    self.save_base(using=using, force_insert=force_insert,
  File "C:\Users\86166\AppData\Local\Programs\Python\Python310\lib\site-packages\django\db\models\base.py", line 780, in save_base
    updated = self._save_table(
  File "C:\Users\86166\AppData\Local\Programs\Python\Python310\lib\site-packages\django\db\models\base.py", line 873, in _save_table
    result = self._do_insert(cls._base_manager, using, fields, update_pk, raw)
  File "C:\Users\86166\AppData\Local\Programs\Python\Python310\lib\site-packages\django\db\models\base.py", line 910, in _do_insert
    return manager._insert([self], fields=fields, return_id=update_pk,
  File "C:\Users\86166\AppData\Local\Programs\Python\Python310\lib\site-packages\django\db\models\manager.py", line 82, in manager_method
    return getattr(self.get_queryset(), name)(*args, **kwargs)
  File "C:\Users\86166\AppData\Local\Programs\Python\Python310\lib\site-packages\django\db\models\query.py", line 1186, in _insert
    return query.get_compiler(using=using).execute_sql(return_id)
  File "C:\Users\86166\AppData\Local\Programs\Python\Python310\lib\site-packages\django\db\models\sql\compiler.py", line 1377, in execute_sql
    cursor.execute(sql, params)
  File "C:\Users\86166\AppData\Local\Programs\Python\Python310\lib\site-packages\django\db\backends\utils.py", line 99, in execute
    return super().execute(sql, params)
  File "C:\Users\86166\AppData\Local\Programs\Python\Python310\lib\site-packages\django\db\backends\utils.py", line 67, in execute
    return self._execute_with_wrappers(sql, params, many=False, executor=self._execute)
  File "C:\Users\86166\AppData\Local\Programs\Python\Python310\lib\site-packages\django\db\backends\utils.py", line 76, in _execute_with_wrappers
    return executor(sql, params, many, context)
  File "C:\Users\86166\AppData\Local\Programs\Python\Python310\lib\site-packages\django\db\backends\utils.py", line 80, in _execute
    with self.db.wrap_database_errors:
  File "C:\Users\86166\AppData\Local\Programs\Python\Python310\lib\site-packages\django\db\utils.py", line 89, in __exit__
    raise dj_exc_value.with_traceback(traceback) from exc_value
  File "C:\Users\86166\AppData\Local\Programs\Python\Python310\lib\site-packages\django\db\backends\utils.py", line 84, in _execute
    return self.cursor.execute(sql, params)
  File "C:\Users\86166\AppData\Local\Programs\Python\Python310\lib\site-packages\django\db\backends\sqlite3\base.py", line 383, in execute
    return Database.Cursor.execute(self, query, params)
django.db.utils.OperationalError: database is locked
INFO - 2023-04-25 03:03:12,450 - process: 7580 - build.py - gerapy.server.core.build - 24 - build - successfully build project spider_ly to egg file E:\tuling\tl\travel\gerapyDemo\gerapy\projects\spider_ly\project-1.0-py3.10.egg
