ERROR - 2023-05-13 01:40:21,434 - process: 2196 - utils.py - gerapy.server.core.utils - 564 - utils - no such table: authtoken_token
Traceback (most recent call last):
  File "C:\Users\86166\AppData\Local\Programs\Python\Python310\lib\site-packages\django\db\backends\utils.py", line 84, in _execute
    return self.cursor.execute(sql, params)
  File "C:\Users\86166\AppData\Local\Programs\Python\Python310\lib\site-packages\django\db\backends\sqlite3\base.py", line 383, in execute
    return Database.Cursor.execute(self, query, params)
sqlite3.OperationalError: no such table: authtoken_token

The above exception was the direct cause of the following exception:

Traceback (most recent call last):
  File "C:\Users\86166\AppData\Local\Programs\Python\Python310\lib\site-packages\gerapy\server\core\utils.py", line 562, in wrapper
    result = func(*args, **kwargs)
  File "C:\Users\86166\AppData\Local\Programs\Python\Python310\lib\site-packages\django\views\decorators\csrf.py", line 54, in wrapped_view
    return view_func(*args, **kwargs)
  File "C:\Users\86166\AppData\Local\Programs\Python\Python310\lib\site-packages\django\views\generic\base.py", line 71, in view
    return self.dispatch(request, *args, **kwargs)
  File "C:\Users\86166\AppData\Local\Programs\Python\Python310\lib\site-packages\rest_framework\views.py", line 509, in dispatch
    response = self.handle_exception(exc)
  File "C:\Users\86166\AppData\Local\Programs\Python\Python310\lib\site-packages\rest_framework\views.py", line 469, in handle_exception
    self.raise_uncaught_exception(exc)
  File "C:\Users\86166\AppData\Local\Programs\Python\Python310\lib\site-packages\rest_framework\views.py", line 480, in raise_uncaught_exception
    raise exc
  File "C:\Users\86166\AppData\Local\Programs\Python\Python310\lib\site-packages\rest_framework\views.py", line 497, in dispatch
    self.initial(request, *args, **kwargs)
  File "C:\Users\86166\AppData\Local\Programs\Python\Python310\lib\site-packages\rest_framework\views.py", line 414, in initial
    self.perform_authentication(request)
  File "C:\Users\86166\AppData\Local\Programs\Python\Python310\lib\site-packages\rest_framework\views.py", line 324, in perform_authentication
    request.user
  File "C:\Users\86166\AppData\Local\Programs\Python\Python310\lib\site-packages\rest_framework\request.py", line 227, in user
    self._authenticate()
  File "C:\Users\86166\AppData\Local\Programs\Python\Python310\lib\site-packages\rest_framework\request.py", line 380, in _authenticate
    user_auth_tuple = authenticator.authenticate(self)
  File "C:\Users\86166\AppData\Local\Programs\Python\Python310\lib\site-packages\rest_framework\authentication.py", line 196, in authenticate
    return self.authenticate_credentials(token)
  File "C:\Users\86166\AppData\Local\Programs\Python\Python310\lib\site-packages\rest_framework\authentication.py", line 201, in authenticate_credentials
    token = model.objects.select_related('user').get(key=key)
  File "C:\Users\86166\AppData\Local\Programs\Python\Python310\lib\site-packages\django\db\models\query.py", line 402, in get
    num = len(clone)
  File "C:\Users\86166\AppData\Local\Programs\Python\Python310\lib\site-packages\django\db\models\query.py", line 256, in __len__
    self._fetch_all()
  File "C:\Users\86166\AppData\Local\Programs\Python\Python310\lib\site-packages\django\db\models\query.py", line 1242, in _fetch_all
    self._result_cache = list(self._iterable_class(self))
  File "C:\Users\86166\AppData\Local\Programs\Python\Python310\lib\site-packages\django\db\models\query.py", line 55, in __iter__
    results = compiler.execute_sql(chunked_fetch=self.chunked_fetch, chunk_size=self.chunk_size)
  File "C:\Users\86166\AppData\Local\Programs\Python\Python310\lib\site-packages\django\db\models\sql\compiler.py", line 1142, in execute_sql
    cursor.execute(sql, params)
  File "C:\Users\86166\AppData\Local\Programs\Python\Python310\lib\site-packages\django\db\backends\utils.py", line 99, in execute
    return super().execute(sql, params)
  File "C:\Users\86166\AppData\Local\Programs\Python\Python310\lib\site-packages\django\db\backends\utils.py", line 67, in execute
    return self._execute_with_wrappers(sql, params, many=False, executor=self._execute)
  File "C:\Users\86166\AppData\Local\Programs\Python\Python310\lib\site-packages\django\db\backends\utils.py", line 76, in _execute_with_wrappers
    return executor(sql, params, many, context)
  File "C:\Users\86166\AppData\Local\Programs\Python\Python310\lib\site-packages\django\db\backends\utils.py", line 80, in _execute
    with self.db.wrap_database_errors:
  File "C:\Users\86166\AppData\Local\Programs\Python\Python310\lib\site-packages\django\db\utils.py", line 89, in __exit__
    raise dj_exc_value.with_traceback(traceback) from exc_value
  File "C:\Users\86166\AppData\Local\Programs\Python\Python310\lib\site-packages\django\db\backends\utils.py", line 84, in _execute
    return self.cursor.execute(sql, params)
  File "C:\Users\86166\AppData\Local\Programs\Python\Python310\lib\site-packages\django\db\backends\sqlite3\base.py", line 383, in execute
    return Database.Cursor.execute(self, query, params)
django.db.utils.OperationalError: no such table: authtoken_token
ERROR - 2023-05-13 01:41:07,312 - process: 2196 - utils.py - gerapy.server.core.utils - 564 - utils - no such table: authtoken_token
Traceback (most recent call last):
  File "C:\Users\86166\AppData\Local\Programs\Python\Python310\lib\site-packages\django\db\backends\utils.py", line 84, in _execute
    return self.cursor.execute(sql, params)
  File "C:\Users\86166\AppData\Local\Programs\Python\Python310\lib\site-packages\django\db\backends\sqlite3\base.py", line 383, in execute
    return Database.Cursor.execute(self, query, params)
sqlite3.OperationalError: no such table: authtoken_token

The above exception was the direct cause of the following exception:

Traceback (most recent call last):
  File "C:\Users\86166\AppData\Local\Programs\Python\Python310\lib\site-packages\gerapy\server\core\utils.py", line 562, in wrapper
    result = func(*args, **kwargs)
  File "C:\Users\86166\AppData\Local\Programs\Python\Python310\lib\site-packages\django\views\decorators\csrf.py", line 54, in wrapped_view
    return view_func(*args, **kwargs)
  File "C:\Users\86166\AppData\Local\Programs\Python\Python310\lib\site-packages\django\views\generic\base.py", line 71, in view
    return self.dispatch(request, *args, **kwargs)
  File "C:\Users\86166\AppData\Local\Programs\Python\Python310\lib\site-packages\rest_framework\views.py", line 509, in dispatch
    response = self.handle_exception(exc)
  File "C:\Users\86166\AppData\Local\Programs\Python\Python310\lib\site-packages\rest_framework\views.py", line 469, in handle_exception
    self.raise_uncaught_exception(exc)
  File "C:\Users\86166\AppData\Local\Programs\Python\Python310\lib\site-packages\rest_framework\views.py", line 480, in raise_uncaught_exception
    raise exc
  File "C:\Users\86166\AppData\Local\Programs\Python\Python310\lib\site-packages\rest_framework\views.py", line 497, in dispatch
    self.initial(request, *args, **kwargs)
  File "C:\Users\86166\AppData\Local\Programs\Python\Python310\lib\site-packages\rest_framework\views.py", line 414, in initial
    self.perform_authentication(request)
  File "C:\Users\86166\AppData\Local\Programs\Python\Python310\lib\site-packages\rest_framework\views.py", line 324, in perform_authentication
    request.user
  File "C:\Users\86166\AppData\Local\Programs\Python\Python310\lib\site-packages\rest_framework\request.py", line 227, in user
    self._authenticate()
  File "C:\Users\86166\AppData\Local\Programs\Python\Python310\lib\site-packages\rest_framework\request.py", line 380, in _authenticate
    user_auth_tuple = authenticator.authenticate(self)
  File "C:\Users\86166\AppData\Local\Programs\Python\Python310\lib\site-packages\rest_framework\authentication.py", line 196, in authenticate
    return self.authenticate_credentials(token)
  File "C:\Users\86166\AppData\Local\Programs\Python\Python310\lib\site-packages\rest_framework\authentication.py", line 201, in authenticate_credentials
    token = model.objects.select_related('user').get(key=key)
  File "C:\Users\86166\AppData\Local\Programs\Python\Python310\lib\site-packages\django\db\models\query.py", line 402, in get
    num = len(clone)
  File "C:\Users\86166\AppData\Local\Programs\Python\Python310\lib\site-packages\django\db\models\query.py", line 256, in __len__
    self._fetch_all()
  File "C:\Users\86166\AppData\Local\Programs\Python\Python310\lib\site-packages\django\db\models\query.py", line 1242, in _fetch_all
    self._result_cache = list(self._iterable_class(self))
  File "C:\Users\86166\AppData\Local\Programs\Python\Python310\lib\site-packages\django\db\models\query.py", line 55, in __iter__
    results = compiler.execute_sql(chunked_fetch=self.chunked_fetch, chunk_size=self.chunk_size)
  File "C:\Users\86166\AppData\Local\Programs\Python\Python310\lib\site-packages\django\db\models\sql\compiler.py", line 1142, in execute_sql
    cursor.execute(sql, params)
  File "C:\Users\86166\AppData\Local\Programs\Python\Python310\lib\site-packages\django\db\backends\utils.py", line 99, in execute
    return super().execute(sql, params)
  File "C:\Users\86166\AppData\Local\Programs\Python\Python310\lib\site-packages\django\db\backends\utils.py", line 67, in execute
    return self._execute_with_wrappers(sql, params, many=False, executor=self._execute)
  File "C:\Users\86166\AppData\Local\Programs\Python\Python310\lib\site-packages\django\db\backends\utils.py", line 76, in _execute_with_wrappers
    return executor(sql, params, many, context)
  File "C:\Users\86166\AppData\Local\Programs\Python\Python310\lib\site-packages\django\db\backends\utils.py", line 80, in _execute
    with self.db.wrap_database_errors:
  File "C:\Users\86166\AppData\Local\Programs\Python\Python310\lib\site-packages\django\db\utils.py", line 89, in __exit__
    raise dj_exc_value.with_traceback(traceback) from exc_value
  File "C:\Users\86166\AppData\Local\Programs\Python\Python310\lib\site-packages\django\db\backends\utils.py", line 84, in _execute
    return self.cursor.execute(sql, params)
  File "C:\Users\86166\AppData\Local\Programs\Python\Python310\lib\site-packages\django\db\backends\sqlite3\base.py", line 383, in execute
    return Database.Cursor.execute(self, query, params)
django.db.utils.OperationalError: no such table: authtoken_token
ERROR - 2023-05-13 01:41:08,520 - process: 2196 - utils.py - gerapy.server.core.utils - 564 - utils - no such table: authtoken_token
Traceback (most recent call last):
  File "C:\Users\86166\AppData\Local\Programs\Python\Python310\lib\site-packages\django\db\backends\utils.py", line 84, in _execute
    return self.cursor.execute(sql, params)
  File "C:\Users\86166\AppData\Local\Programs\Python\Python310\lib\site-packages\django\db\backends\sqlite3\base.py", line 383, in execute
    return Database.Cursor.execute(self, query, params)
sqlite3.OperationalError: no such table: authtoken_token

The above exception was the direct cause of the following exception:

Traceback (most recent call last):
  File "C:\Users\86166\AppData\Local\Programs\Python\Python310\lib\site-packages\gerapy\server\core\utils.py", line 562, in wrapper
    result = func(*args, **kwargs)
  File "C:\Users\86166\AppData\Local\Programs\Python\Python310\lib\site-packages\django\views\decorators\csrf.py", line 54, in wrapped_view
    return view_func(*args, **kwargs)
  File "C:\Users\86166\AppData\Local\Programs\Python\Python310\lib\site-packages\django\views\generic\base.py", line 71, in view
    return self.dispatch(request, *args, **kwargs)
  File "C:\Users\86166\AppData\Local\Programs\Python\Python310\lib\site-packages\rest_framework\views.py", line 509, in dispatch
    response = self.handle_exception(exc)
  File "C:\Users\86166\AppData\Local\Programs\Python\Python310\lib\site-packages\rest_framework\views.py", line 469, in handle_exception
    self.raise_uncaught_exception(exc)
  File "C:\Users\86166\AppData\Local\Programs\Python\Python310\lib\site-packages\rest_framework\views.py", line 480, in raise_uncaught_exception
    raise exc
  File "C:\Users\86166\AppData\Local\Programs\Python\Python310\lib\site-packages\rest_framework\views.py", line 497, in dispatch
    self.initial(request, *args, **kwargs)
  File "C:\Users\86166\AppData\Local\Programs\Python\Python310\lib\site-packages\rest_framework\views.py", line 414, in initial
    self.perform_authentication(request)
  File "C:\Users\86166\AppData\Local\Programs\Python\Python310\lib\site-packages\rest_framework\views.py", line 324, in perform_authentication
    request.user
  File "C:\Users\86166\AppData\Local\Programs\Python\Python310\lib\site-packages\rest_framework\request.py", line 227, in user
    self._authenticate()
  File "C:\Users\86166\AppData\Local\Programs\Python\Python310\lib\site-packages\rest_framework\request.py", line 380, in _authenticate
    user_auth_tuple = authenticator.authenticate(self)
  File "C:\Users\86166\AppData\Local\Programs\Python\Python310\lib\site-packages\rest_framework\authentication.py", line 196, in authenticate
    return self.authenticate_credentials(token)
  File "C:\Users\86166\AppData\Local\Programs\Python\Python310\lib\site-packages\rest_framework\authentication.py", line 201, in authenticate_credentials
    token = model.objects.select_related('user').get(key=key)
  File "C:\Users\86166\AppData\Local\Programs\Python\Python310\lib\site-packages\django\db\models\query.py", line 402, in get
    num = len(clone)
  File "C:\Users\86166\AppData\Local\Programs\Python\Python310\lib\site-packages\django\db\models\query.py", line 256, in __len__
    self._fetch_all()
  File "C:\Users\86166\AppData\Local\Programs\Python\Python310\lib\site-packages\django\db\models\query.py", line 1242, in _fetch_all
    self._result_cache = list(self._iterable_class(self))
  File "C:\Users\86166\AppData\Local\Programs\Python\Python310\lib\site-packages\django\db\models\query.py", line 55, in __iter__
    results = compiler.execute_sql(chunked_fetch=self.chunked_fetch, chunk_size=self.chunk_size)
  File "C:\Users\86166\AppData\Local\Programs\Python\Python310\lib\site-packages\django\db\models\sql\compiler.py", line 1142, in execute_sql
    cursor.execute(sql, params)
  File "C:\Users\86166\AppData\Local\Programs\Python\Python310\lib\site-packages\django\db\backends\utils.py", line 99, in execute
    return super().execute(sql, params)
  File "C:\Users\86166\AppData\Local\Programs\Python\Python310\lib\site-packages\django\db\backends\utils.py", line 67, in execute
    return self._execute_with_wrappers(sql, params, many=False, executor=self._execute)
  File "C:\Users\86166\AppData\Local\Programs\Python\Python310\lib\site-packages\django\db\backends\utils.py", line 76, in _execute_with_wrappers
    return executor(sql, params, many, context)
  File "C:\Users\86166\AppData\Local\Programs\Python\Python310\lib\site-packages\django\db\backends\utils.py", line 80, in _execute
    with self.db.wrap_database_errors:
  File "C:\Users\86166\AppData\Local\Programs\Python\Python310\lib\site-packages\django\db\utils.py", line 89, in __exit__
    raise dj_exc_value.with_traceback(traceback) from exc_value
  File "C:\Users\86166\AppData\Local\Programs\Python\Python310\lib\site-packages\django\db\backends\utils.py", line 84, in _execute
    return self.cursor.execute(sql, params)
  File "C:\Users\86166\AppData\Local\Programs\Python\Python310\lib\site-packages\django\db\backends\sqlite3\base.py", line 383, in execute
    return Database.Cursor.execute(self, query, params)
django.db.utils.OperationalError: no such table: authtoken_token
ERROR - 2023-05-13 01:41:14,582 - process: 2196 - utils.py - gerapy.server.core.utils - 564 - utils - no such table: authtoken_token
Traceback (most recent call last):
  File "C:\Users\86166\AppData\Local\Programs\Python\Python310\lib\site-packages\django\db\backends\utils.py", line 84, in _execute
    return self.cursor.execute(sql, params)
  File "C:\Users\86166\AppData\Local\Programs\Python\Python310\lib\site-packages\django\db\backends\sqlite3\base.py", line 383, in execute
    return Database.Cursor.execute(self, query, params)
sqlite3.OperationalError: no such table: authtoken_token

The above exception was the direct cause of the following exception:

Traceback (most recent call last):
  File "C:\Users\86166\AppData\Local\Programs\Python\Python310\lib\site-packages\gerapy\server\core\utils.py", line 562, in wrapper
    result = func(*args, **kwargs)
  File "C:\Users\86166\AppData\Local\Programs\Python\Python310\lib\site-packages\django\views\decorators\csrf.py", line 54, in wrapped_view
    return view_func(*args, **kwargs)
  File "C:\Users\86166\AppData\Local\Programs\Python\Python310\lib\site-packages\django\views\generic\base.py", line 71, in view
    return self.dispatch(request, *args, **kwargs)
  File "C:\Users\86166\AppData\Local\Programs\Python\Python310\lib\site-packages\rest_framework\views.py", line 509, in dispatch
    response = self.handle_exception(exc)
  File "C:\Users\86166\AppData\Local\Programs\Python\Python310\lib\site-packages\rest_framework\views.py", line 469, in handle_exception
    self.raise_uncaught_exception(exc)
  File "C:\Users\86166\AppData\Local\Programs\Python\Python310\lib\site-packages\rest_framework\views.py", line 480, in raise_uncaught_exception
    raise exc
  File "C:\Users\86166\AppData\Local\Programs\Python\Python310\lib\site-packages\rest_framework\views.py", line 497, in dispatch
    self.initial(request, *args, **kwargs)
  File "C:\Users\86166\AppData\Local\Programs\Python\Python310\lib\site-packages\rest_framework\views.py", line 414, in initial
    self.perform_authentication(request)
  File "C:\Users\86166\AppData\Local\Programs\Python\Python310\lib\site-packages\rest_framework\views.py", line 324, in perform_authentication
    request.user
  File "C:\Users\86166\AppData\Local\Programs\Python\Python310\lib\site-packages\rest_framework\request.py", line 227, in user
    self._authenticate()
  File "C:\Users\86166\AppData\Local\Programs\Python\Python310\lib\site-packages\rest_framework\request.py", line 380, in _authenticate
    user_auth_tuple = authenticator.authenticate(self)
  File "C:\Users\86166\AppData\Local\Programs\Python\Python310\lib\site-packages\rest_framework\authentication.py", line 196, in authenticate
    return self.authenticate_credentials(token)
  File "C:\Users\86166\AppData\Local\Programs\Python\Python310\lib\site-packages\rest_framework\authentication.py", line 201, in authenticate_credentials
    token = model.objects.select_related('user').get(key=key)
  File "C:\Users\86166\AppData\Local\Programs\Python\Python310\lib\site-packages\django\db\models\query.py", line 402, in get
    num = len(clone)
  File "C:\Users\86166\AppData\Local\Programs\Python\Python310\lib\site-packages\django\db\models\query.py", line 256, in __len__
    self._fetch_all()
  File "C:\Users\86166\AppData\Local\Programs\Python\Python310\lib\site-packages\django\db\models\query.py", line 1242, in _fetch_all
    self._result_cache = list(self._iterable_class(self))
  File "C:\Users\86166\AppData\Local\Programs\Python\Python310\lib\site-packages\django\db\models\query.py", line 55, in __iter__
    results = compiler.execute_sql(chunked_fetch=self.chunked_fetch, chunk_size=self.chunk_size)
  File "C:\Users\86166\AppData\Local\Programs\Python\Python310\lib\site-packages\django\db\models\sql\compiler.py", line 1142, in execute_sql
    cursor.execute(sql, params)
  File "C:\Users\86166\AppData\Local\Programs\Python\Python310\lib\site-packages\django\db\backends\utils.py", line 99, in execute
    return super().execute(sql, params)
  File "C:\Users\86166\AppData\Local\Programs\Python\Python310\lib\site-packages\django\db\backends\utils.py", line 67, in execute
    return self._execute_with_wrappers(sql, params, many=False, executor=self._execute)
  File "C:\Users\86166\AppData\Local\Programs\Python\Python310\lib\site-packages\django\db\backends\utils.py", line 76, in _execute_with_wrappers
    return executor(sql, params, many, context)
  File "C:\Users\86166\AppData\Local\Programs\Python\Python310\lib\site-packages\django\db\backends\utils.py", line 80, in _execute
    with self.db.wrap_database_errors:
  File "C:\Users\86166\AppData\Local\Programs\Python\Python310\lib\site-packages\django\db\utils.py", line 89, in __exit__
    raise dj_exc_value.with_traceback(traceback) from exc_value
  File "C:\Users\86166\AppData\Local\Programs\Python\Python310\lib\site-packages\django\db\backends\utils.py", line 84, in _execute
    return self.cursor.execute(sql, params)
  File "C:\Users\86166\AppData\Local\Programs\Python\Python310\lib\site-packages\django\db\backends\sqlite3\base.py", line 383, in execute
    return Database.Cursor.execute(self, query, params)
django.db.utils.OperationalError: no such table: authtoken_token
ERROR - 2023-05-13 01:41:16,881 - process: 2196 - utils.py - gerapy.server.core.utils - 564 - utils - no such table: authtoken_token
Traceback (most recent call last):
  File "C:\Users\86166\AppData\Local\Programs\Python\Python310\lib\site-packages\django\db\backends\utils.py", line 84, in _execute
    return self.cursor.execute(sql, params)
  File "C:\Users\86166\AppData\Local\Programs\Python\Python310\lib\site-packages\django\db\backends\sqlite3\base.py", line 383, in execute
    return Database.Cursor.execute(self, query, params)
sqlite3.OperationalError: no such table: authtoken_token

The above exception was the direct cause of the following exception:

Traceback (most recent call last):
  File "C:\Users\86166\AppData\Local\Programs\Python\Python310\lib\site-packages\gerapy\server\core\utils.py", line 562, in wrapper
    result = func(*args, **kwargs)
  File "C:\Users\86166\AppData\Local\Programs\Python\Python310\lib\site-packages\django\views\decorators\csrf.py", line 54, in wrapped_view
    return view_func(*args, **kwargs)
  File "C:\Users\86166\AppData\Local\Programs\Python\Python310\lib\site-packages\django\views\generic\base.py", line 71, in view
    return self.dispatch(request, *args, **kwargs)
  File "C:\Users\86166\AppData\Local\Programs\Python\Python310\lib\site-packages\rest_framework\views.py", line 509, in dispatch
    response = self.handle_exception(exc)
  File "C:\Users\86166\AppData\Local\Programs\Python\Python310\lib\site-packages\rest_framework\views.py", line 469, in handle_exception
    self.raise_uncaught_exception(exc)
  File "C:\Users\86166\AppData\Local\Programs\Python\Python310\lib\site-packages\rest_framework\views.py", line 480, in raise_uncaught_exception
    raise exc
  File "C:\Users\86166\AppData\Local\Programs\Python\Python310\lib\site-packages\rest_framework\views.py", line 497, in dispatch
    self.initial(request, *args, **kwargs)
  File "C:\Users\86166\AppData\Local\Programs\Python\Python310\lib\site-packages\rest_framework\views.py", line 414, in initial
    self.perform_authentication(request)
  File "C:\Users\86166\AppData\Local\Programs\Python\Python310\lib\site-packages\rest_framework\views.py", line 324, in perform_authentication
    request.user
  File "C:\Users\86166\AppData\Local\Programs\Python\Python310\lib\site-packages\rest_framework\request.py", line 227, in user
    self._authenticate()
  File "C:\Users\86166\AppData\Local\Programs\Python\Python310\lib\site-packages\rest_framework\request.py", line 380, in _authenticate
    user_auth_tuple = authenticator.authenticate(self)
  File "C:\Users\86166\AppData\Local\Programs\Python\Python310\lib\site-packages\rest_framework\authentication.py", line 196, in authenticate
    return self.authenticate_credentials(token)
  File "C:\Users\86166\AppData\Local\Programs\Python\Python310\lib\site-packages\rest_framework\authentication.py", line 201, in authenticate_credentials
    token = model.objects.select_related('user').get(key=key)
  File "C:\Users\86166\AppData\Local\Programs\Python\Python310\lib\site-packages\django\db\models\query.py", line 402, in get
    num = len(clone)
  File "C:\Users\86166\AppData\Local\Programs\Python\Python310\lib\site-packages\django\db\models\query.py", line 256, in __len__
    self._fetch_all()
  File "C:\Users\86166\AppData\Local\Programs\Python\Python310\lib\site-packages\django\db\models\query.py", line 1242, in _fetch_all
    self._result_cache = list(self._iterable_class(self))
  File "C:\Users\86166\AppData\Local\Programs\Python\Python310\lib\site-packages\django\db\models\query.py", line 55, in __iter__
    results = compiler.execute_sql(chunked_fetch=self.chunked_fetch, chunk_size=self.chunk_size)
  File "C:\Users\86166\AppData\Local\Programs\Python\Python310\lib\site-packages\django\db\models\sql\compiler.py", line 1142, in execute_sql
    cursor.execute(sql, params)
  File "C:\Users\86166\AppData\Local\Programs\Python\Python310\lib\site-packages\django\db\backends\utils.py", line 99, in execute
    return super().execute(sql, params)
  File "C:\Users\86166\AppData\Local\Programs\Python\Python310\lib\site-packages\django\db\backends\utils.py", line 67, in execute
    return self._execute_with_wrappers(sql, params, many=False, executor=self._execute)
  File "C:\Users\86166\AppData\Local\Programs\Python\Python310\lib\site-packages\django\db\backends\utils.py", line 76, in _execute_with_wrappers
    return executor(sql, params, many, context)
  File "C:\Users\86166\AppData\Local\Programs\Python\Python310\lib\site-packages\django\db\backends\utils.py", line 80, in _execute
    with self.db.wrap_database_errors:
  File "C:\Users\86166\AppData\Local\Programs\Python\Python310\lib\site-packages\django\db\utils.py", line 89, in __exit__
    raise dj_exc_value.with_traceback(traceback) from exc_value
  File "C:\Users\86166\AppData\Local\Programs\Python\Python310\lib\site-packages\django\db\backends\utils.py", line 84, in _execute
    return self.cursor.execute(sql, params)
  File "C:\Users\86166\AppData\Local\Programs\Python\Python310\lib\site-packages\django\db\backends\sqlite3\base.py", line 383, in execute
    return Database.Cursor.execute(self, query, params)
django.db.utils.OperationalError: no such table: authtoken_token
ERROR - 2023-05-13 01:41:18,882 - process: 2196 - utils.py - gerapy.server.core.utils - 564 - utils - no such table: authtoken_token
Traceback (most recent call last):
  File "C:\Users\86166\AppData\Local\Programs\Python\Python310\lib\site-packages\django\db\backends\utils.py", line 84, in _execute
    return self.cursor.execute(sql, params)
  File "C:\Users\86166\AppData\Local\Programs\Python\Python310\lib\site-packages\django\db\backends\sqlite3\base.py", line 383, in execute
    return Database.Cursor.execute(self, query, params)
sqlite3.OperationalError: no such table: authtoken_token

The above exception was the direct cause of the following exception:

Traceback (most recent call last):
  File "C:\Users\86166\AppData\Local\Programs\Python\Python310\lib\site-packages\gerapy\server\core\utils.py", line 562, in wrapper
    result = func(*args, **kwargs)
  File "C:\Users\86166\AppData\Local\Programs\Python\Python310\lib\site-packages\django\views\decorators\csrf.py", line 54, in wrapped_view
    return view_func(*args, **kwargs)
  File "C:\Users\86166\AppData\Local\Programs\Python\Python310\lib\site-packages\django\views\generic\base.py", line 71, in view
    return self.dispatch(request, *args, **kwargs)
  File "C:\Users\86166\AppData\Local\Programs\Python\Python310\lib\site-packages\rest_framework\views.py", line 509, in dispatch
    response = self.handle_exception(exc)
  File "C:\Users\86166\AppData\Local\Programs\Python\Python310\lib\site-packages\rest_framework\views.py", line 469, in handle_exception
    self.raise_uncaught_exception(exc)
  File "C:\Users\86166\AppData\Local\Programs\Python\Python310\lib\site-packages\rest_framework\views.py", line 480, in raise_uncaught_exception
    raise exc
  File "C:\Users\86166\AppData\Local\Programs\Python\Python310\lib\site-packages\rest_framework\views.py", line 497, in dispatch
    self.initial(request, *args, **kwargs)
  File "C:\Users\86166\AppData\Local\Programs\Python\Python310\lib\site-packages\rest_framework\views.py", line 414, in initial
    self.perform_authentication(request)
  File "C:\Users\86166\AppData\Local\Programs\Python\Python310\lib\site-packages\rest_framework\views.py", line 324, in perform_authentication
    request.user
  File "C:\Users\86166\AppData\Local\Programs\Python\Python310\lib\site-packages\rest_framework\request.py", line 227, in user
    self._authenticate()
  File "C:\Users\86166\AppData\Local\Programs\Python\Python310\lib\site-packages\rest_framework\request.py", line 380, in _authenticate
    user_auth_tuple = authenticator.authenticate(self)
  File "C:\Users\86166\AppData\Local\Programs\Python\Python310\lib\site-packages\rest_framework\authentication.py", line 196, in authenticate
    return self.authenticate_credentials(token)
  File "C:\Users\86166\AppData\Local\Programs\Python\Python310\lib\site-packages\rest_framework\authentication.py", line 201, in authenticate_credentials
    token = model.objects.select_related('user').get(key=key)
  File "C:\Users\86166\AppData\Local\Programs\Python\Python310\lib\site-packages\django\db\models\query.py", line 402, in get
    num = len(clone)
  File "C:\Users\86166\AppData\Local\Programs\Python\Python310\lib\site-packages\django\db\models\query.py", line 256, in __len__
    self._fetch_all()
  File "C:\Users\86166\AppData\Local\Programs\Python\Python310\lib\site-packages\django\db\models\query.py", line 1242, in _fetch_all
    self._result_cache = list(self._iterable_class(self))
  File "C:\Users\86166\AppData\Local\Programs\Python\Python310\lib\site-packages\django\db\models\query.py", line 55, in __iter__
    results = compiler.execute_sql(chunked_fetch=self.chunked_fetch, chunk_size=self.chunk_size)
  File "C:\Users\86166\AppData\Local\Programs\Python\Python310\lib\site-packages\django\db\models\sql\compiler.py", line 1142, in execute_sql
    cursor.execute(sql, params)
  File "C:\Users\86166\AppData\Local\Programs\Python\Python310\lib\site-packages\django\db\backends\utils.py", line 99, in execute
    return super().execute(sql, params)
  File "C:\Users\86166\AppData\Local\Programs\Python\Python310\lib\site-packages\django\db\backends\utils.py", line 67, in execute
    return self._execute_with_wrappers(sql, params, many=False, executor=self._execute)
  File "C:\Users\86166\AppData\Local\Programs\Python\Python310\lib\site-packages\django\db\backends\utils.py", line 76, in _execute_with_wrappers
    return executor(sql, params, many, context)
  File "C:\Users\86166\AppData\Local\Programs\Python\Python310\lib\site-packages\django\db\backends\utils.py", line 80, in _execute
    with self.db.wrap_database_errors:
  File "C:\Users\86166\AppData\Local\Programs\Python\Python310\lib\site-packages\django\db\utils.py", line 89, in __exit__
    raise dj_exc_value.with_traceback(traceback) from exc_value
  File "C:\Users\86166\AppData\Local\Programs\Python\Python310\lib\site-packages\django\db\backends\utils.py", line 84, in _execute
    return self.cursor.execute(sql, params)
  File "C:\Users\86166\AppData\Local\Programs\Python\Python310\lib\site-packages\django\db\backends\sqlite3\base.py", line 383, in execute
    return Database.Cursor.execute(self, query, params)
django.db.utils.OperationalError: no such table: authtoken_token
ERROR - 2023-05-13 01:41:19,501 - process: 2196 - utils.py - gerapy.server.core.utils - 564 - utils - no such table: authtoken_token
Traceback (most recent call last):
  File "C:\Users\86166\AppData\Local\Programs\Python\Python310\lib\site-packages\django\db\backends\utils.py", line 84, in _execute
    return self.cursor.execute(sql, params)
  File "C:\Users\86166\AppData\Local\Programs\Python\Python310\lib\site-packages\django\db\backends\sqlite3\base.py", line 383, in execute
    return Database.Cursor.execute(self, query, params)
sqlite3.OperationalError: no such table: authtoken_token

The above exception was the direct cause of the following exception:

Traceback (most recent call last):
  File "C:\Users\86166\AppData\Local\Programs\Python\Python310\lib\site-packages\gerapy\server\core\utils.py", line 562, in wrapper
    result = func(*args, **kwargs)
  File "C:\Users\86166\AppData\Local\Programs\Python\Python310\lib\site-packages\django\views\decorators\csrf.py", line 54, in wrapped_view
    return view_func(*args, **kwargs)
  File "C:\Users\86166\AppData\Local\Programs\Python\Python310\lib\site-packages\django\views\generic\base.py", line 71, in view
    return self.dispatch(request, *args, **kwargs)
  File "C:\Users\86166\AppData\Local\Programs\Python\Python310\lib\site-packages\rest_framework\views.py", line 509, in dispatch
    response = self.handle_exception(exc)
  File "C:\Users\86166\AppData\Local\Programs\Python\Python310\lib\site-packages\rest_framework\views.py", line 469, in handle_exception
    self.raise_uncaught_exception(exc)
  File "C:\Users\86166\AppData\Local\Programs\Python\Python310\lib\site-packages\rest_framework\views.py", line 480, in raise_uncaught_exception
    raise exc
  File "C:\Users\86166\AppData\Local\Programs\Python\Python310\lib\site-packages\rest_framework\views.py", line 497, in dispatch
    self.initial(request, *args, **kwargs)
  File "C:\Users\86166\AppData\Local\Programs\Python\Python310\lib\site-packages\rest_framework\views.py", line 414, in initial
    self.perform_authentication(request)
  File "C:\Users\86166\AppData\Local\Programs\Python\Python310\lib\site-packages\rest_framework\views.py", line 324, in perform_authentication
    request.user
  File "C:\Users\86166\AppData\Local\Programs\Python\Python310\lib\site-packages\rest_framework\request.py", line 227, in user
    self._authenticate()
  File "C:\Users\86166\AppData\Local\Programs\Python\Python310\lib\site-packages\rest_framework\request.py", line 380, in _authenticate
    user_auth_tuple = authenticator.authenticate(self)
  File "C:\Users\86166\AppData\Local\Programs\Python\Python310\lib\site-packages\rest_framework\authentication.py", line 196, in authenticate
    return self.authenticate_credentials(token)
  File "C:\Users\86166\AppData\Local\Programs\Python\Python310\lib\site-packages\rest_framework\authentication.py", line 201, in authenticate_credentials
    token = model.objects.select_related('user').get(key=key)
  File "C:\Users\86166\AppData\Local\Programs\Python\Python310\lib\site-packages\django\db\models\query.py", line 402, in get
    num = len(clone)
  File "C:\Users\86166\AppData\Local\Programs\Python\Python310\lib\site-packages\django\db\models\query.py", line 256, in __len__
    self._fetch_all()
  File "C:\Users\86166\AppData\Local\Programs\Python\Python310\lib\site-packages\django\db\models\query.py", line 1242, in _fetch_all
    self._result_cache = list(self._iterable_class(self))
  File "C:\Users\86166\AppData\Local\Programs\Python\Python310\lib\site-packages\django\db\models\query.py", line 55, in __iter__
    results = compiler.execute_sql(chunked_fetch=self.chunked_fetch, chunk_size=self.chunk_size)
  File "C:\Users\86166\AppData\Local\Programs\Python\Python310\lib\site-packages\django\db\models\sql\compiler.py", line 1142, in execute_sql
    cursor.execute(sql, params)
  File "C:\Users\86166\AppData\Local\Programs\Python\Python310\lib\site-packages\django\db\backends\utils.py", line 99, in execute
    return super().execute(sql, params)
  File "C:\Users\86166\AppData\Local\Programs\Python\Python310\lib\site-packages\django\db\backends\utils.py", line 67, in execute
    return self._execute_with_wrappers(sql, params, many=False, executor=self._execute)
  File "C:\Users\86166\AppData\Local\Programs\Python\Python310\lib\site-packages\django\db\backends\utils.py", line 76, in _execute_with_wrappers
    return executor(sql, params, many, context)
  File "C:\Users\86166\AppData\Local\Programs\Python\Python310\lib\site-packages\django\db\backends\utils.py", line 80, in _execute
    with self.db.wrap_database_errors:
  File "C:\Users\86166\AppData\Local\Programs\Python\Python310\lib\site-packages\django\db\utils.py", line 89, in __exit__
    raise dj_exc_value.with_traceback(traceback) from exc_value
  File "C:\Users\86166\AppData\Local\Programs\Python\Python310\lib\site-packages\django\db\backends\utils.py", line 84, in _execute
    return self.cursor.execute(sql, params)
  File "C:\Users\86166\AppData\Local\Programs\Python\Python310\lib\site-packages\django\db\backends\sqlite3\base.py", line 383, in execute
    return Database.Cursor.execute(self, query, params)
django.db.utils.OperationalError: no such table: authtoken_token
ERROR - 2023-05-13 01:41:20,306 - process: 2196 - utils.py - gerapy.server.core.utils - 564 - utils - no such table: authtoken_token
Traceback (most recent call last):
  File "C:\Users\86166\AppData\Local\Programs\Python\Python310\lib\site-packages\django\db\backends\utils.py", line 84, in _execute
    return self.cursor.execute(sql, params)
  File "C:\Users\86166\AppData\Local\Programs\Python\Python310\lib\site-packages\django\db\backends\sqlite3\base.py", line 383, in execute
    return Database.Cursor.execute(self, query, params)
sqlite3.OperationalError: no such table: authtoken_token

The above exception was the direct cause of the following exception:

Traceback (most recent call last):
  File "C:\Users\86166\AppData\Local\Programs\Python\Python310\lib\site-packages\gerapy\server\core\utils.py", line 562, in wrapper
    result = func(*args, **kwargs)
  File "C:\Users\86166\AppData\Local\Programs\Python\Python310\lib\site-packages\django\views\decorators\csrf.py", line 54, in wrapped_view
    return view_func(*args, **kwargs)
  File "C:\Users\86166\AppData\Local\Programs\Python\Python310\lib\site-packages\django\views\generic\base.py", line 71, in view
    return self.dispatch(request, *args, **kwargs)
  File "C:\Users\86166\AppData\Local\Programs\Python\Python310\lib\site-packages\rest_framework\views.py", line 509, in dispatch
    response = self.handle_exception(exc)
  File "C:\Users\86166\AppData\Local\Programs\Python\Python310\lib\site-packages\rest_framework\views.py", line 469, in handle_exception
    self.raise_uncaught_exception(exc)
  File "C:\Users\86166\AppData\Local\Programs\Python\Python310\lib\site-packages\rest_framework\views.py", line 480, in raise_uncaught_exception
    raise exc
  File "C:\Users\86166\AppData\Local\Programs\Python\Python310\lib\site-packages\rest_framework\views.py", line 497, in dispatch
    self.initial(request, *args, **kwargs)
  File "C:\Users\86166\AppData\Local\Programs\Python\Python310\lib\site-packages\rest_framework\views.py", line 414, in initial
    self.perform_authentication(request)
  File "C:\Users\86166\AppData\Local\Programs\Python\Python310\lib\site-packages\rest_framework\views.py", line 324, in perform_authentication
    request.user
  File "C:\Users\86166\AppData\Local\Programs\Python\Python310\lib\site-packages\rest_framework\request.py", line 227, in user
    self._authenticate()
  File "C:\Users\86166\AppData\Local\Programs\Python\Python310\lib\site-packages\rest_framework\request.py", line 380, in _authenticate
    user_auth_tuple = authenticator.authenticate(self)
  File "C:\Users\86166\AppData\Local\Programs\Python\Python310\lib\site-packages\rest_framework\authentication.py", line 196, in authenticate
    return self.authenticate_credentials(token)
  File "C:\Users\86166\AppData\Local\Programs\Python\Python310\lib\site-packages\rest_framework\authentication.py", line 201, in authenticate_credentials
    token = model.objects.select_related('user').get(key=key)
  File "C:\Users\86166\AppData\Local\Programs\Python\Python310\lib\site-packages\django\db\models\query.py", line 402, in get
    num = len(clone)
  File "C:\Users\86166\AppData\Local\Programs\Python\Python310\lib\site-packages\django\db\models\query.py", line 256, in __len__
    self._fetch_all()
  File "C:\Users\86166\AppData\Local\Programs\Python\Python310\lib\site-packages\django\db\models\query.py", line 1242, in _fetch_all
    self._result_cache = list(self._iterable_class(self))
  File "C:\Users\86166\AppData\Local\Programs\Python\Python310\lib\site-packages\django\db\models\query.py", line 55, in __iter__
    results = compiler.execute_sql(chunked_fetch=self.chunked_fetch, chunk_size=self.chunk_size)
  File "C:\Users\86166\AppData\Local\Programs\Python\Python310\lib\site-packages\django\db\models\sql\compiler.py", line 1142, in execute_sql
    cursor.execute(sql, params)
  File "C:\Users\86166\AppData\Local\Programs\Python\Python310\lib\site-packages\django\db\backends\utils.py", line 99, in execute
    return super().execute(sql, params)
  File "C:\Users\86166\AppData\Local\Programs\Python\Python310\lib\site-packages\django\db\backends\utils.py", line 67, in execute
    return self._execute_with_wrappers(sql, params, many=False, executor=self._execute)
  File "C:\Users\86166\AppData\Local\Programs\Python\Python310\lib\site-packages\django\db\backends\utils.py", line 76, in _execute_with_wrappers
    return executor(sql, params, many, context)
  File "C:\Users\86166\AppData\Local\Programs\Python\Python310\lib\site-packages\django\db\backends\utils.py", line 80, in _execute
    with self.db.wrap_database_errors:
  File "C:\Users\86166\AppData\Local\Programs\Python\Python310\lib\site-packages\django\db\utils.py", line 89, in __exit__
    raise dj_exc_value.with_traceback(traceback) from exc_value
  File "C:\Users\86166\AppData\Local\Programs\Python\Python310\lib\site-packages\django\db\backends\utils.py", line 84, in _execute
    return self.cursor.execute(sql, params)
  File "C:\Users\86166\AppData\Local\Programs\Python\Python310\lib\site-packages\django\db\backends\sqlite3\base.py", line 383, in execute
    return Database.Cursor.execute(self, query, params)
django.db.utils.OperationalError: no such table: authtoken_token
ERROR - 2023-05-13 01:41:21,359 - process: 2196 - utils.py - gerapy.server.core.utils - 564 - utils - no such table: authtoken_token
Traceback (most recent call last):
  File "C:\Users\86166\AppData\Local\Programs\Python\Python310\lib\site-packages\django\db\backends\utils.py", line 84, in _execute
    return self.cursor.execute(sql, params)
  File "C:\Users\86166\AppData\Local\Programs\Python\Python310\lib\site-packages\django\db\backends\sqlite3\base.py", line 383, in execute
    return Database.Cursor.execute(self, query, params)
sqlite3.OperationalError: no such table: authtoken_token

The above exception was the direct cause of the following exception:

Traceback (most recent call last):
  File "C:\Users\86166\AppData\Local\Programs\Python\Python310\lib\site-packages\gerapy\server\core\utils.py", line 562, in wrapper
    result = func(*args, **kwargs)
  File "C:\Users\86166\AppData\Local\Programs\Python\Python310\lib\site-packages\django\views\decorators\csrf.py", line 54, in wrapped_view
    return view_func(*args, **kwargs)
  File "C:\Users\86166\AppData\Local\Programs\Python\Python310\lib\site-packages\django\views\generic\base.py", line 71, in view
    return self.dispatch(request, *args, **kwargs)
  File "C:\Users\86166\AppData\Local\Programs\Python\Python310\lib\site-packages\rest_framework\views.py", line 509, in dispatch
    response = self.handle_exception(exc)
  File "C:\Users\86166\AppData\Local\Programs\Python\Python310\lib\site-packages\rest_framework\views.py", line 469, in handle_exception
    self.raise_uncaught_exception(exc)
  File "C:\Users\86166\AppData\Local\Programs\Python\Python310\lib\site-packages\rest_framework\views.py", line 480, in raise_uncaught_exception
    raise exc
  File "C:\Users\86166\AppData\Local\Programs\Python\Python310\lib\site-packages\rest_framework\views.py", line 497, in dispatch
    self.initial(request, *args, **kwargs)
  File "C:\Users\86166\AppData\Local\Programs\Python\Python310\lib\site-packages\rest_framework\views.py", line 414, in initial
    self.perform_authentication(request)
  File "C:\Users\86166\AppData\Local\Programs\Python\Python310\lib\site-packages\rest_framework\views.py", line 324, in perform_authentication
    request.user
  File "C:\Users\86166\AppData\Local\Programs\Python\Python310\lib\site-packages\rest_framework\request.py", line 227, in user
    self._authenticate()
  File "C:\Users\86166\AppData\Local\Programs\Python\Python310\lib\site-packages\rest_framework\request.py", line 380, in _authenticate
    user_auth_tuple = authenticator.authenticate(self)
  File "C:\Users\86166\AppData\Local\Programs\Python\Python310\lib\site-packages\rest_framework\authentication.py", line 196, in authenticate
    return self.authenticate_credentials(token)
  File "C:\Users\86166\AppData\Local\Programs\Python\Python310\lib\site-packages\rest_framework\authentication.py", line 201, in authenticate_credentials
    token = model.objects.select_related('user').get(key=key)
  File "C:\Users\86166\AppData\Local\Programs\Python\Python310\lib\site-packages\django\db\models\query.py", line 402, in get
    num = len(clone)
  File "C:\Users\86166\AppData\Local\Programs\Python\Python310\lib\site-packages\django\db\models\query.py", line 256, in __len__
    self._fetch_all()
  File "C:\Users\86166\AppData\Local\Programs\Python\Python310\lib\site-packages\django\db\models\query.py", line 1242, in _fetch_all
    self._result_cache = list(self._iterable_class(self))
  File "C:\Users\86166\AppData\Local\Programs\Python\Python310\lib\site-packages\django\db\models\query.py", line 55, in __iter__
    results = compiler.execute_sql(chunked_fetch=self.chunked_fetch, chunk_size=self.chunk_size)
  File "C:\Users\86166\AppData\Local\Programs\Python\Python310\lib\site-packages\django\db\models\sql\compiler.py", line 1142, in execute_sql
    cursor.execute(sql, params)
  File "C:\Users\86166\AppData\Local\Programs\Python\Python310\lib\site-packages\django\db\backends\utils.py", line 99, in execute
    return super().execute(sql, params)
  File "C:\Users\86166\AppData\Local\Programs\Python\Python310\lib\site-packages\django\db\backends\utils.py", line 67, in execute
    return self._execute_with_wrappers(sql, params, many=False, executor=self._execute)
  File "C:\Users\86166\AppData\Local\Programs\Python\Python310\lib\site-packages\django\db\backends\utils.py", line 76, in _execute_with_wrappers
    return executor(sql, params, many, context)
  File "C:\Users\86166\AppData\Local\Programs\Python\Python310\lib\site-packages\django\db\backends\utils.py", line 80, in _execute
    with self.db.wrap_database_errors:
  File "C:\Users\86166\AppData\Local\Programs\Python\Python310\lib\site-packages\django\db\utils.py", line 89, in __exit__
    raise dj_exc_value.with_traceback(traceback) from exc_value
  File "C:\Users\86166\AppData\Local\Programs\Python\Python310\lib\site-packages\django\db\backends\utils.py", line 84, in _execute
    return self.cursor.execute(sql, params)
  File "C:\Users\86166\AppData\Local\Programs\Python\Python310\lib\site-packages\django\db\backends\sqlite3\base.py", line 383, in execute
    return Database.Cursor.execute(self, query, params)
django.db.utils.OperationalError: no such table: authtoken_token
ERROR - 2023-05-13 01:41:21,989 - process: 2196 - utils.py - gerapy.server.core.utils - 564 - utils - no such table: authtoken_token
Traceback (most recent call last):
  File "C:\Users\86166\AppData\Local\Programs\Python\Python310\lib\site-packages\django\db\backends\utils.py", line 84, in _execute
    return self.cursor.execute(sql, params)
  File "C:\Users\86166\AppData\Local\Programs\Python\Python310\lib\site-packages\django\db\backends\sqlite3\base.py", line 383, in execute
    return Database.Cursor.execute(self, query, params)
sqlite3.OperationalError: no such table: authtoken_token

The above exception was the direct cause of the following exception:

Traceback (most recent call last):
  File "C:\Users\86166\AppData\Local\Programs\Python\Python310\lib\site-packages\gerapy\server\core\utils.py", line 562, in wrapper
    result = func(*args, **kwargs)
  File "C:\Users\86166\AppData\Local\Programs\Python\Python310\lib\site-packages\django\views\decorators\csrf.py", line 54, in wrapped_view
    return view_func(*args, **kwargs)
  File "C:\Users\86166\AppData\Local\Programs\Python\Python310\lib\site-packages\django\views\generic\base.py", line 71, in view
    return self.dispatch(request, *args, **kwargs)
  File "C:\Users\86166\AppData\Local\Programs\Python\Python310\lib\site-packages\rest_framework\views.py", line 509, in dispatch
    response = self.handle_exception(exc)
  File "C:\Users\86166\AppData\Local\Programs\Python\Python310\lib\site-packages\rest_framework\views.py", line 469, in handle_exception
    self.raise_uncaught_exception(exc)
  File "C:\Users\86166\AppData\Local\Programs\Python\Python310\lib\site-packages\rest_framework\views.py", line 480, in raise_uncaught_exception
    raise exc
  File "C:\Users\86166\AppData\Local\Programs\Python\Python310\lib\site-packages\rest_framework\views.py", line 497, in dispatch
    self.initial(request, *args, **kwargs)
  File "C:\Users\86166\AppData\Local\Programs\Python\Python310\lib\site-packages\rest_framework\views.py", line 414, in initial
    self.perform_authentication(request)
  File "C:\Users\86166\AppData\Local\Programs\Python\Python310\lib\site-packages\rest_framework\views.py", line 324, in perform_authentication
    request.user
  File "C:\Users\86166\AppData\Local\Programs\Python\Python310\lib\site-packages\rest_framework\request.py", line 227, in user
    self._authenticate()
  File "C:\Users\86166\AppData\Local\Programs\Python\Python310\lib\site-packages\rest_framework\request.py", line 380, in _authenticate
    user_auth_tuple = authenticator.authenticate(self)
  File "C:\Users\86166\AppData\Local\Programs\Python\Python310\lib\site-packages\rest_framework\authentication.py", line 196, in authenticate
    return self.authenticate_credentials(token)
  File "C:\Users\86166\AppData\Local\Programs\Python\Python310\lib\site-packages\rest_framework\authentication.py", line 201, in authenticate_credentials
    token = model.objects.select_related('user').get(key=key)
  File "C:\Users\86166\AppData\Local\Programs\Python\Python310\lib\site-packages\django\db\models\query.py", line 402, in get
    num = len(clone)
  File "C:\Users\86166\AppData\Local\Programs\Python\Python310\lib\site-packages\django\db\models\query.py", line 256, in __len__
    self._fetch_all()
  File "C:\Users\86166\AppData\Local\Programs\Python\Python310\lib\site-packages\django\db\models\query.py", line 1242, in _fetch_all
    self._result_cache = list(self._iterable_class(self))
  File "C:\Users\86166\AppData\Local\Programs\Python\Python310\lib\site-packages\django\db\models\query.py", line 55, in __iter__
    results = compiler.execute_sql(chunked_fetch=self.chunked_fetch, chunk_size=self.chunk_size)
  File "C:\Users\86166\AppData\Local\Programs\Python\Python310\lib\site-packages\django\db\models\sql\compiler.py", line 1142, in execute_sql
    cursor.execute(sql, params)
  File "C:\Users\86166\AppData\Local\Programs\Python\Python310\lib\site-packages\django\db\backends\utils.py", line 99, in execute
    return super().execute(sql, params)
  File "C:\Users\86166\AppData\Local\Programs\Python\Python310\lib\site-packages\django\db\backends\utils.py", line 67, in execute
    return self._execute_with_wrappers(sql, params, many=False, executor=self._execute)
  File "C:\Users\86166\AppData\Local\Programs\Python\Python310\lib\site-packages\django\db\backends\utils.py", line 76, in _execute_with_wrappers
    return executor(sql, params, many, context)
  File "C:\Users\86166\AppData\Local\Programs\Python\Python310\lib\site-packages\django\db\backends\utils.py", line 80, in _execute
    with self.db.wrap_database_errors:
  File "C:\Users\86166\AppData\Local\Programs\Python\Python310\lib\site-packages\django\db\utils.py", line 89, in __exit__
    raise dj_exc_value.with_traceback(traceback) from exc_value
  File "C:\Users\86166\AppData\Local\Programs\Python\Python310\lib\site-packages\django\db\backends\utils.py", line 84, in _execute
    return self.cursor.execute(sql, params)
  File "C:\Users\86166\AppData\Local\Programs\Python\Python310\lib\site-packages\django\db\backends\sqlite3\base.py", line 383, in execute
    return Database.Cursor.execute(self, query, params)
django.db.utils.OperationalError: no such table: authtoken_token
ERROR - 2023-05-13 01:41:22,603 - process: 2196 - utils.py - gerapy.server.core.utils - 564 - utils - no such table: authtoken_token
Traceback (most recent call last):
  File "C:\Users\86166\AppData\Local\Programs\Python\Python310\lib\site-packages\django\db\backends\utils.py", line 84, in _execute
    return self.cursor.execute(sql, params)
  File "C:\Users\86166\AppData\Local\Programs\Python\Python310\lib\site-packages\django\db\backends\sqlite3\base.py", line 383, in execute
    return Database.Cursor.execute(self, query, params)
sqlite3.OperationalError: no such table: authtoken_token

The above exception was the direct cause of the following exception:

Traceback (most recent call last):
  File "C:\Users\86166\AppData\Local\Programs\Python\Python310\lib\site-packages\gerapy\server\core\utils.py", line 562, in wrapper
    result = func(*args, **kwargs)
  File "C:\Users\86166\AppData\Local\Programs\Python\Python310\lib\site-packages\django\views\decorators\csrf.py", line 54, in wrapped_view
    return view_func(*args, **kwargs)
  File "C:\Users\86166\AppData\Local\Programs\Python\Python310\lib\site-packages\django\views\generic\base.py", line 71, in view
    return self.dispatch(request, *args, **kwargs)
  File "C:\Users\86166\AppData\Local\Programs\Python\Python310\lib\site-packages\rest_framework\views.py", line 509, in dispatch
    response = self.handle_exception(exc)
  File "C:\Users\86166\AppData\Local\Programs\Python\Python310\lib\site-packages\rest_framework\views.py", line 469, in handle_exception
    self.raise_uncaught_exception(exc)
  File "C:\Users\86166\AppData\Local\Programs\Python\Python310\lib\site-packages\rest_framework\views.py", line 480, in raise_uncaught_exception
    raise exc
  File "C:\Users\86166\AppData\Local\Programs\Python\Python310\lib\site-packages\rest_framework\views.py", line 497, in dispatch
    self.initial(request, *args, **kwargs)
  File "C:\Users\86166\AppData\Local\Programs\Python\Python310\lib\site-packages\rest_framework\views.py", line 414, in initial
    self.perform_authentication(request)
  File "C:\Users\86166\AppData\Local\Programs\Python\Python310\lib\site-packages\rest_framework\views.py", line 324, in perform_authentication
    request.user
  File "C:\Users\86166\AppData\Local\Programs\Python\Python310\lib\site-packages\rest_framework\request.py", line 227, in user
    self._authenticate()
  File "C:\Users\86166\AppData\Local\Programs\Python\Python310\lib\site-packages\rest_framework\request.py", line 380, in _authenticate
    user_auth_tuple = authenticator.authenticate(self)
  File "C:\Users\86166\AppData\Local\Programs\Python\Python310\lib\site-packages\rest_framework\authentication.py", line 196, in authenticate
    return self.authenticate_credentials(token)
  File "C:\Users\86166\AppData\Local\Programs\Python\Python310\lib\site-packages\rest_framework\authentication.py", line 201, in authenticate_credentials
    token = model.objects.select_related('user').get(key=key)
  File "C:\Users\86166\AppData\Local\Programs\Python\Python310\lib\site-packages\django\db\models\query.py", line 402, in get
    num = len(clone)
  File "C:\Users\86166\AppData\Local\Programs\Python\Python310\lib\site-packages\django\db\models\query.py", line 256, in __len__
    self._fetch_all()
  File "C:\Users\86166\AppData\Local\Programs\Python\Python310\lib\site-packages\django\db\models\query.py", line 1242, in _fetch_all
    self._result_cache = list(self._iterable_class(self))
  File "C:\Users\86166\AppData\Local\Programs\Python\Python310\lib\site-packages\django\db\models\query.py", line 55, in __iter__
    results = compiler.execute_sql(chunked_fetch=self.chunked_fetch, chunk_size=self.chunk_size)
  File "C:\Users\86166\AppData\Local\Programs\Python\Python310\lib\site-packages\django\db\models\sql\compiler.py", line 1142, in execute_sql
    cursor.execute(sql, params)
  File "C:\Users\86166\AppData\Local\Programs\Python\Python310\lib\site-packages\django\db\backends\utils.py", line 99, in execute
    return super().execute(sql, params)
  File "C:\Users\86166\AppData\Local\Programs\Python\Python310\lib\site-packages\django\db\backends\utils.py", line 67, in execute
    return self._execute_with_wrappers(sql, params, many=False, executor=self._execute)
  File "C:\Users\86166\AppData\Local\Programs\Python\Python310\lib\site-packages\django\db\backends\utils.py", line 76, in _execute_with_wrappers
    return executor(sql, params, many, context)
  File "C:\Users\86166\AppData\Local\Programs\Python\Python310\lib\site-packages\django\db\backends\utils.py", line 80, in _execute
    with self.db.wrap_database_errors:
  File "C:\Users\86166\AppData\Local\Programs\Python\Python310\lib\site-packages\django\db\utils.py", line 89, in __exit__
    raise dj_exc_value.with_traceback(traceback) from exc_value
  File "C:\Users\86166\AppData\Local\Programs\Python\Python310\lib\site-packages\django\db\backends\utils.py", line 84, in _execute
    return self.cursor.execute(sql, params)
  File "C:\Users\86166\AppData\Local\Programs\Python\Python310\lib\site-packages\django\db\backends\sqlite3\base.py", line 383, in execute
    return Database.Cursor.execute(self, query, params)
django.db.utils.OperationalError: no such table: authtoken_token
ERROR - 2023-05-13 01:41:40,739 - process: 2196 - utils.py - gerapy.server.core.utils - 564 - utils - no such table: authtoken_token
Traceback (most recent call last):
  File "C:\Users\86166\AppData\Local\Programs\Python\Python310\lib\site-packages\django\db\backends\utils.py", line 84, in _execute
    return self.cursor.execute(sql, params)
  File "C:\Users\86166\AppData\Local\Programs\Python\Python310\lib\site-packages\django\db\backends\sqlite3\base.py", line 383, in execute
    return Database.Cursor.execute(self, query, params)
sqlite3.OperationalError: no such table: authtoken_token

The above exception was the direct cause of the following exception:

Traceback (most recent call last):
  File "C:\Users\86166\AppData\Local\Programs\Python\Python310\lib\site-packages\gerapy\server\core\utils.py", line 562, in wrapper
    result = func(*args, **kwargs)
  File "C:\Users\86166\AppData\Local\Programs\Python\Python310\lib\site-packages\django\views\decorators\csrf.py", line 54, in wrapped_view
    return view_func(*args, **kwargs)
  File "C:\Users\86166\AppData\Local\Programs\Python\Python310\lib\site-packages\django\views\generic\base.py", line 71, in view
    return self.dispatch(request, *args, **kwargs)
  File "C:\Users\86166\AppData\Local\Programs\Python\Python310\lib\site-packages\rest_framework\views.py", line 509, in dispatch
    response = self.handle_exception(exc)
  File "C:\Users\86166\AppData\Local\Programs\Python\Python310\lib\site-packages\rest_framework\views.py", line 469, in handle_exception
    self.raise_uncaught_exception(exc)
  File "C:\Users\86166\AppData\Local\Programs\Python\Python310\lib\site-packages\rest_framework\views.py", line 480, in raise_uncaught_exception
    raise exc
  File "C:\Users\86166\AppData\Local\Programs\Python\Python310\lib\site-packages\rest_framework\views.py", line 497, in dispatch
    self.initial(request, *args, **kwargs)
  File "C:\Users\86166\AppData\Local\Programs\Python\Python310\lib\site-packages\rest_framework\views.py", line 414, in initial
    self.perform_authentication(request)
  File "C:\Users\86166\AppData\Local\Programs\Python\Python310\lib\site-packages\rest_framework\views.py", line 324, in perform_authentication
    request.user
  File "C:\Users\86166\AppData\Local\Programs\Python\Python310\lib\site-packages\rest_framework\request.py", line 227, in user
    self._authenticate()
  File "C:\Users\86166\AppData\Local\Programs\Python\Python310\lib\site-packages\rest_framework\request.py", line 380, in _authenticate
    user_auth_tuple = authenticator.authenticate(self)
  File "C:\Users\86166\AppData\Local\Programs\Python\Python310\lib\site-packages\rest_framework\authentication.py", line 196, in authenticate
    return self.authenticate_credentials(token)
  File "C:\Users\86166\AppData\Local\Programs\Python\Python310\lib\site-packages\rest_framework\authentication.py", line 201, in authenticate_credentials
    token = model.objects.select_related('user').get(key=key)
  File "C:\Users\86166\AppData\Local\Programs\Python\Python310\lib\site-packages\django\db\models\query.py", line 402, in get
    num = len(clone)
  File "C:\Users\86166\AppData\Local\Programs\Python\Python310\lib\site-packages\django\db\models\query.py", line 256, in __len__
    self._fetch_all()
  File "C:\Users\86166\AppData\Local\Programs\Python\Python310\lib\site-packages\django\db\models\query.py", line 1242, in _fetch_all
    self._result_cache = list(self._iterable_class(self))
  File "C:\Users\86166\AppData\Local\Programs\Python\Python310\lib\site-packages\django\db\models\query.py", line 55, in __iter__
    results = compiler.execute_sql(chunked_fetch=self.chunked_fetch, chunk_size=self.chunk_size)
  File "C:\Users\86166\AppData\Local\Programs\Python\Python310\lib\site-packages\django\db\models\sql\compiler.py", line 1142, in execute_sql
    cursor.execute(sql, params)
  File "C:\Users\86166\AppData\Local\Programs\Python\Python310\lib\site-packages\django\db\backends\utils.py", line 99, in execute
    return super().execute(sql, params)
  File "C:\Users\86166\AppData\Local\Programs\Python\Python310\lib\site-packages\django\db\backends\utils.py", line 67, in execute
    return self._execute_with_wrappers(sql, params, many=False, executor=self._execute)
  File "C:\Users\86166\AppData\Local\Programs\Python\Python310\lib\site-packages\django\db\backends\utils.py", line 76, in _execute_with_wrappers
    return executor(sql, params, many, context)
  File "C:\Users\86166\AppData\Local\Programs\Python\Python310\lib\site-packages\django\db\backends\utils.py", line 80, in _execute
    with self.db.wrap_database_errors:
  File "C:\Users\86166\AppData\Local\Programs\Python\Python310\lib\site-packages\django\db\utils.py", line 89, in __exit__
    raise dj_exc_value.with_traceback(traceback) from exc_value
  File "C:\Users\86166\AppData\Local\Programs\Python\Python310\lib\site-packages\django\db\backends\utils.py", line 84, in _execute
    return self.cursor.execute(sql, params)
  File "C:\Users\86166\AppData\Local\Programs\Python\Python310\lib\site-packages\django\db\backends\sqlite3\base.py", line 383, in execute
    return Database.Cursor.execute(self, query, params)
django.db.utils.OperationalError: no such table: authtoken_token
